Workbook
Name chartBossCounts: Dashboard!$X$4:INDEX(Dashboard!$X$4:$X$53,COUNTA(Dashboard!$W$4:$W$53))
Name chartBossNames: Dashboard!$W$4:INDEX(Dashboard!$W$4:$W$53,COUNTA(Dashboard!$W$4:$W$53))
Name chartClassCounts: Dashboard!$AI$209:INDEX(Dashboard!#REF!,COUNTA(Dashboard!$K$209:$K$228))
Name chartClassNames: Dashboard!$AH$209:INDEX(Dashboard!$K$209:$K$228,COUNTA(Dashboard!$K$209:$K$228))
Name chartPlayerCounts: Dashboard!$E$3:INDEX(Dashboard!$E$3:$E$202,COUNTA(Dashboard!$D$3:$D$202))
Name chartPlayerNames: Dashboard!$D$3:INDEX(Dashboard!$D$3:$D$202,COUNTA(Dashboard!$D$3:$D$202))
Name chartRaidCounts: Dashboard!$AA$4:INDEX(Dashboard!$AA$4:$AA$53,COUNTA(Dashboard!$Z$4:$Z$53))
Name chartRaidLabels: Dashboard!$Z$4:INDEX(Dashboard!$Z$4:$Z$53,COUNTA(Dashboard!$Z$4:$Z$53))
Name chartRespCounts: Dashboard!$AE$209:$AE$214
Name chartRespLabels: Dashboard!$AD$209:$AD$214
Name message: 'Loot History'!$A$1:$T$52

Sheet Loot History
A1: player | B1: date | C1: time | D1: item | E1: itemID | F1: itemString | G1: response | H1: votes | I1: class | J1: instance | K1: boss | L1: gear1 | M1: gear2 | N1: responseID | O1: isAwardReason | P1: rollType | Q1: subType | R1: equipLoc | S1: note | T1: owner | U1: RaidDate
A2: Klaaw-Thunderstrike | B2: 46160 | C2: 0.91111111 | D2: Gloves of the Vanquished Hero | E2: 30241 | F2: item:30241::::::::70 | G2: BiS | H2: 2 | I2: HUNTER | J2: Coilfang: Serpentshrine Cavern-25 Player | K2: Leotheras the Blind | L2: Handguards of the Beast Lord | M2: n/a | N2: 1 | O2: FALSE | P2: normal | Q2: Armor Token | T2: Heislbärt-Thunderstrike | U2: =IF(B2="","",B2) -> 46160
A3: Alàén-Thunderstrike | B3: 46160 | C3: 0.86111111 | D3: Chestguard of the Ranger-General | E3: 30054 | F3: item:30054::::::::70 | G3: Upgrade | H3: 0 | I3: PALADIN | J3: Coilfang: Serpentshrine Cavern-25 Player | K3: Hydross the Unstable | L3: Chestguard of the Conspirator | M3: n/a | N3: 3 | O3: FALSE | P3: normal | Q3: Mail | R3: Chest | T3: Heislbärt-Thunderstrike | U3: =IF(B3="","",B3) -> 46160
A4: Alàén-Thunderstrike | B4: 46160 | C4: 0.87638889 | D4: Brighthelm of Justice | E4: 30065 | F4: item:30065::::::::70 | G4: Offspecc | H4: 4 | I4: PALADIN | J4: Coilfang: Serpentshrine Cavern-25 Player | K4: Hydross the Unstable | L4: Chestguard of the Conspirator | M4: n/a | N4: 4 | O4: FALSE | P4: normal | Q4: Plate | R4: Chest | T4: Heislbärt-Thunderstrike | U4: =IF(B4="","",B4) -> 46160
A5: Alàén-Thunderstrike | B5: 46160 | C5: 0.87708333 | D5: Ancestral Ring of Conquest | E5: 30061 | F5: item:30061::::::::70 | G5: 2nd BiS | H5: 1 | I5: PALADIN | J5: Coilfang: Serpentshrine Cavern-25 Player | K5: The Lurker Below | L5: Shapeshifter's Signet | M5: A'dal's Command | N5: 2 | O5: FALSE | P5: normal | Q5: Miscellaneous | R5: Finger | T5: Heislbärt-Thunderstrike | U5: =IF(B5="","",B5) -> 46160
A6: Alàén-Thunderstrike | B6: 46160 | C6: 0.91041667 | D6: World Breaker | E6: 30090 | F6: item:30090::::::::70 | G6: 2nd BiS | H6: 6 | I6: PALADIN | J6: Coilfang: Serpentshrine Cavern-25 Player | K6: Fathom-Lord Karathress | L6: Gorehowl | M6: n/a | N6: 2 | O6: FALSE | P6: normal | Q6: Two-Handed Maces | R6: Two-Hand | T6: Heislbärt-Thunderstrike | U6: =IF(B6="","",B6) -> 46160
A7: Mardinez-Thunderstrike | B7: 46160 | C7: 0.87708333 | D7: Earring of Soulful Meditation | E7: 30665 | F7: item:30665::::::::70 | G7: 2nd BiS | H7: 5 | I7: PRIEST | J7: Coilfang: Serpentshrine Cavern-25 Player | K7: The Lurker Below | L7: Essence of the Martyr | M7: Ribbon of Sacrifice | N7: 2 | O7: FALSE | P7: normal | Q7: Miscellaneous | R7: Trinket | T7: Heislbärt-Thunderstrike | U7: =IF(B7="","",B7) -> 46160
A8: Heislbärt-Thunderstrike | B8: 46160 | C8: 0.97916667 | D8: Belt of One-Hundred Deaths | E8: 30106 | F8: item:30106::::::::70 | G8: BiS | H8: 3 | I8: DRUID | J8: Coilfang: Serpentshrine Cavern-25 Player | K8: Lady Vashj | L8: Girdle of Treachery | M8: n/a | N8: 1 | O8: FALSE | P8: normal | Q8: Leather | R8: Waist | T8: Heislbärt-Thunderstrike | U8: =IF(B8="","",B8) -> 46160
A9: Zerleger-Thunderstrike | B9: 46160 | C9: 0.8875 | D9: Nether Vortex | E9: 30183 | F9: item:30183::::::::70 | G9: BiS | H9: 3 | I9: WARRIOR | J9: Coilfang: Serpentshrine Cavern-25 Player | K9: SSC / TK Trash | M9: n/a | N9: 1 | O9: FALSE | P9: normal | Q9: Materials | T9: Heislbärt-Thunderstrike | U9: =IF(B9="","",B9) -> 46160
A10: Zerleger-Thunderstrike | B10: 46160 | C10: 0.90972222 | D10: Serpentshrine Shuriken | E10: 30025 | F10: item:30025::::::::70 | G10: Upgrade | H10: 5 | I10: WARRIOR | J10: Coilfang: Serpentshrine Cavern-25 Player | K10: SSC Trash | L10: Sunfury Bow of the Phoenix | M10: n/a | N10: 3 | O10: FALSE | P10: normal | Q10: Thrown | R10: Thrown | T10: Heislbärt-Thunderstrike | U10: =IF(B10="","",B10) -> 46160
A11: Zerleger-Thunderstrike | B11: 46160 | C11: 0.91041667 | D11: Pattern: Boots of the Long Road | E11: 30283 | F11: item:30283::::::::70 | G11: Pass | H11: 0 | I11: WARRIOR | J11: Coilfang: Serpentshrine Cavern-25 Player | K11: SSC Trash | M11: n/a | N11: PASS | O11: FALSE | P11: normal | Q11: Tailoring | T11: Heislbärt-Thunderstrike | U11: =IF(B11="","",B11) -> 46160
A12: Tastycake-Thunderstrike | B12: 46160 | C12: 0.90902778 | D12: Pendant of Long Lost Memories | E12: 30008 | F12: item:30008::::::::70 | G12: Upgrade | H12: 5 | I12: MAGE | J12: Coilfang: Serpentshrine Cavern-25 Player | K12: SSC Trash | L12: Sethekk Prophet's Ring | M12: n/a | N12: 3 | O12: FALSE | P12: normal | Q12: Miscellaneous | R12: Neck | T12: Heislbärt-Thunderstrike | U12: =IF(B12="","",B12) -> 46160
A13: Flieege-Thunderstrike | B13: 46160 | C13: 0.97916667 | D13: Helm of the Vanquished Hero | E13: 30244 | F13: item:30244::::::::70 | G13: BiS | H13: 0 | I13: WARLOCK | J13: Coilfang: Serpentshrine Cavern-25 Player | K13: Lady Vashj | L13: Crown of the Voidheart | M13: n/a | N13: 1 | O13: FALSE | P13: normal | Q13: Armor Token | T13: Flieege-Thunderstrike | U13: =IF(B13="","",B13) -> 46160
A14: Oßa-Thunderstrike | B14: 46160 | C14: 0.90902778 | D14: Leggings of the Vanquished Champion | E14: 30245 | F14: item:30245::::::::70 | G14: BiS | H14: 1 | I14: SHAMAN | J14: Coilfang: Serpentshrine Cavern-25 Player | K14: Fathom-Lord Karathress | L14: Leggings of the Heartfire | M14: n/a | N14: 1 | O14: FALSE | P14: normal | Q14: Armor Token | T14: Heislbärt-Thunderstrike | U14: =IF(B14="","",B14) -> 46160
A15: Oßa-Thunderstrike | B15: 46160 | C15: 0.91041667 | D15: Spiked Coral Shoulderpads | E15: 30097 | F15: item:30097::::::::70 | G15: Upgrade | H15: 5 | I15: SHAMAN | J15: Coilfang: Serpentshrine Cavern-25 Player | K15: SSC Trash | L15: Shoulderpads of the Hurricane | M15: n/a | N15: 3 | O15: FALSE | P15: normal | Q15: Mail | R15: Shoulder | T15: Heislbärt-Thunderstrike | U15: =IF(B15="","",B15) -> 46160
A16: Keindaemon-Thunderstrike | B16: 46160 | C16: 0.8625 | D16: Living Root of the Wildheart | E16: 30664 | F16: item:30664::::::::70 | G16: Upgrade | H16: 2 | I16: DRUID | J16: Coilfang: Serpentshrine Cavern-25 Player | K16: Hydross the Unstable | L16: Alchemist Stone | M16: Xi'ri's Gift | N16: 3 | O16: FALSE | P16: normal | Q16: Miscellaneous | R16: Trinket | T16: Heislbärt-Thunderstrike | U16: =IF(B16="","",B16) -> 46160
A17: Ribsz-Thunderstrike | B17: 46160 | C17: 0.91180556 | D17: Gloves of the Vanquished Hero | E17: 30241 | F17: item:30241::::::::70 | G17: BiS | H17: 0 | I17: MAGE | J17: Coilfang: Serpentshrine Cavern-25 Player | K17: Leotheras the Blind | L17: Spellfire Gloves | M17: n/a | N17: 1 | O17: FALSE | P17: normal | Q17: Armor Token | T17: Heislbärt-Thunderstrike | U17: =IF(B17="","",B17) -> 46160
A18: Zzou-Thunderstrike | B18: 46160 | C18: 0.86180556 | D18: Ring of Lethality | E18: 30052 | F18: item:30052::::::::70 | G18: BiS | H18: 3 | I18: HUNTER | J18: Coilfang: Serpentshrine Cavern-25 Player | K18: Hydross the Unstable | L18: Violet Signet | M18: Ring of Shadowy Doom | N18: 1 | O18: FALSE | P18: normal | Q18: Miscellaneous | R18: Finger | S18: bis #1 sv | T18: Heislbärt-Thunderstrike | U18: =IF(B18="","",B18) -> 46160
A19: Zabipala-Thunderstrike | B19: 46160 | C19: 0.90902778 | D19: Leggings of the Vanquished Champion | E19: 30245 | F19: item:30245::::::::70 | G19: BiS | H19: 4 | I19: PALADIN | J19: Coilfang: Serpentshrine Cavern-25 Player | K19: Fathom-Lord Karathress | L19: Legguards of the Justicar | M19: n/a | N19: 1 | O19: FALSE | P19: normal | Q19: Armor Token | T19: Heislbärt-Thunderstrike | U19: =IF(B19="","",B19) -> 46160
A20: Zabipala-Thunderstrike | B20: 46160 | C20: 0.91041667 | D20: Gloves of the Vanquished Champion | E20: 30239 | F20: item:30239::::::::70 | G20: BiS | H20: 2 | I20: PALADIN | J20: Coilfang: Serpentshrine Cavern-25 Player | K20: Leotheras the Blind | L20: Handguards of the Justicar | M20: n/a | N20: 1 | O20: FALSE | P20: normal | Q20: Armor Token | T20: Heislbärt-Thunderstrike | U20: =IF(B20="","",B20) -> 46160
A21: Zabipala-Thunderstrike | B21: 46160 | C21: 0.97847222 | D21: Helm of the Vanquished Champion | E21: 30242 | F21: item:30242::::::::70 | G21: BiS | H21: 1 | I21: PALADIN | J21: Coilfang: Serpentshrine Cavern-25 Player | K21: Lady Vashj | L21: Panzatronic Goggles | M21: n/a | N21: 1 | O21: FALSE | P21: normal | Q21: Armor Token | T21: Zabipala-Thunderstrike | U21: =IF(B21="","",B21) -> 46160
A22: Xænd-Thunderstrike | B22: 46160 | C22: 0.90902778 | D22: Warboots of Obliteration | E22: 30081 | F22: item:30081::::::::70 | G22: BiS | H22: 2 | I22: WARRIOR | J22: Coilfang: Serpentshrine Cavern-25 Player | K22: Morogrim Tidewalker | L22: Ironstriders of Urgency | M22: n/a | N22: 1 | O22: FALSE | P22: normal | Q22: Plate | R22: Feet | T22: Heislbärt-Thunderstrike | U22: =IF(B22="","",B22) -> 46160
A23: Tommypenn-Thunderstrike | B23: 46160 | C23: 0.87777778 | D23: Totem of the Maelstrom | E23: 30023 | F23: item:30023::::::::70 | G23: Offspecc | H23: 2 | I23: SHAMAN | J23: Coilfang: Serpentshrine Cavern-25 Player | K23: SSC Trash | M23: n/a | N23: 4 | O23: FALSE | P23: normal | Q23: Totems | R23: Relic | T23: Heislbärt-Thunderstrike | U23: =IF(B23="","",B23) -> 46160
A24: Tommypenn-Thunderstrike | B24: 46160 | C24: 0.90902778 | D24: Leggings of the Vanquished Champion | E24: 30245 | F24: item:30245::::::::70 | G24: BiS | H24: 1 | I24: SHAMAN | J24: Coilfang: Serpentshrine Cavern-25 Player | K24: Fathom-Lord Karathress | L24: Spellstrike Pants | M24: n/a | N24: 1 | O24: FALSE | P24: normal | Q24: Armor Token | T24: Heislbärt-Thunderstrike | U24: =IF(B24="","",B24) -> 46160
A25: Spewspew-Thunderstrike | B25: 46160 | C25: 0.90902778 | D25: Serpent-Coil Braid | E25: 30720 | F25: item:30720::::::::70 | G25: BiS | H25: 3 | I25: MAGE | J25: Coilfang: Serpentshrine Cavern-25 Player | K25: Morogrim Tidewalker | L25: Icon of the Silver Crescent | M25: The Lightning Capacitor | N25: 1 | O25: FALSE | P25: normal | Q25: Miscellaneous | R25: Trinket | T25: Heislbärt-Thunderstrike | U25: =IF(B25="","",B25) -> 46160
A26: Mommyfrieren-Thunderstrike | B26: 46160 | C26: 0.98055556 | D26: Ring of the Endless Coils | E26: 30109 | F26: item:30109::::::::70 | G26: BiS | H26: 5 | I26: WARLOCK | J26: Coilfang: Serpentshrine Cavern-25 Player | K26: Lady Vashj | L26: Band of the Crimson Fury | M26: Ring of Recurrence | N26: 1 | O26: FALSE | P26: normal | Q26: Miscellaneous | R26: Finger | T26: Mommyfrieren-Thunderstrike | U26: =IF(B26="","",B26) -> 46160
A27: Gerdarogers-Thunderstrike | B27: 46160 | C27: 0.97916667 | D27: Helm of the Vanquished Hero | E27: 30244 | F27: item:30244::::::::70 | G27: BiS | H27: 1 | I27: WARLOCK | J27: Coilfang: Serpentshrine Cavern-25 Player | K27: Lady Vashj | L27: Crown of the Voidheart | M27: n/a | N27: 1 | O27: FALSE | P27: normal | Q27: Armor Token | T27: Gerdarogers-Thunderstrike | U27: =IF(B27="","",B27) -> 46160
A28: Lilyasx-Thunderstrike | B28: 46161 | C28: 0.90069444 | D28: Bark-Gloves of Ancient Wisdom | E28: 30029 | F28: item:30029::::::::70 | G28: Upgrade | H28: 2 | I28: DRUID | J28: Tempest Keep-25 Player | K28: TK Trash | L28: Hallowed Handwraps | M28: n/a | N28: 3 | O28: FALSE | P28: normal | Q28: Leather | R28: Hands | S28: super low prio | T28: Lilyasx-Thunderstrike | U28: =IF(B28="","",B28) -> 46161
A29: Fetzine-Thunderstrike | B29: 46161 | C29: 0.90138889 | D29: Arcanite Steam-Pistol | E29: 29949 | F29: item:29949::::::::70 | G29: 2nd BiS | H29: 3 | I29: HUNTER | J29: Tempest Keep-25 Player | K29: Al'ar | L29: Sunfury Bow of the Phoenix | M29: n/a | N29: 2 | O29: FALSE | P29: normal | Q29: Guns | R29: Ranged | T29: Lilyasx-Thunderstrike | U29: =IF(B29="","",B29) -> 46161
A30: Zerleger-Thunderstrike | B30: 46161 | C30: 0.91111111 | D30: Fel-Steel Warhelm | E30: 29983 | F30: item:29983::::::::70 | G30: Upgrade | H30: 1 | I30: WARRIOR | J30: Tempest Keep-25 Player | K30: Void Reaver | L30: Warbringer Greathelm | M30: n/a | N30: 3 | O30: FALSE | P30: normal | Q30: Plate | R30: Head | T30: Lilyasx-Thunderstrike | U30: =IF(B30="","",B30) -> 46161
A31: Zerleger-Thunderstrike | B31: 46161 | C31: 0.92986111 | D31: Pauldrons of the Vanquished Defender | E31: 30249 | F31: item:30249::::::::70 | G31: BiS | H31: 0 | I31: WARRIOR | J31: Tempest Keep-25 Player | K31: Void Reaver | L31: Warbringer Shoulderguards | M31: n/a | N31: 1 | O31: FALSE | P31: normal | Q31: Armor Token | T31: Lilyasx-Thunderstrike | U31: =IF(B31="","",B31) -> 46161
A32: Keindaemon-Thunderstrike | B32: 46161 | C32: 0.90069444 | D32: Mindstorm Wristbands | E32: 29918 | F32: item:29918::::::::70 | G32: BiS | H32: 3 | I32: DRUID | J32: Tempest Keep-25 Player | K32: Al'ar | L32: Bracers of the White Stag | M32: n/a | N32: 1 | O32: FALSE | P32: normal | Q32: Cloth | R32: Wrist | T32: Lilyasx-Thunderstrike | U32: =IF(B32="","",B32) -> 46161
A33: Zabipala-Thunderstrike | B33: 46161 | C33: 0.93055556 | D33: Boots of the Resilient | E33: 32267 | F33: item:32267::::::::70 | G33: BiS | H33: 1 | I33: PALADIN | J33: Tempest Keep-25 Player | K33: High Astromancer Solarian | L33: Boots of the Righteous Path | M33: n/a | N33: 1 | O33: FALSE | P33: normal | Q33: Plate | R33: Feet | T33: Lilyasx-Thunderstrike | U33: =IF(B33="","",B33) -> 46161
A34: Zabipala-Thunderstrike | B34: 46161 | C34: 0.93055556 | D34: Seventh Ring of the Tirisfalen | E34: 30028 | F34: item:30028::::::::70 | G34: BiS | H34: 1 | I34: PALADIN | J34: Tempest Keep-25 Player | K34: TK Trash | L34: Violet Signet of the Great Protector | M34: Ring of Unyielding Force | N34: 1 | O34: FALSE | P34: normal | Q34: Miscellaneous | R34: Finger | T34: Lilyasx-Thunderstrike | U34: =IF(B34="","",B34) -> 46161
A35: Xænd-Thunderstrike | B35: 46161 | C35: 0.90208333 | D35: Netherbane | E35: 29924 | F35: item:29924::::::::70 | G35: 2nd BiS | H35: 2 | I35: WARRIOR | J35: Tempest Keep-25 Player | K35: Al'ar | L35: Dragonmaw | M35: Fel Edged Battleaxe | N35: 2 | O35: FALSE | P35: normal | Q35: One-Handed Axes | R35: One-Hand | T35: Lilyasx-Thunderstrike | U35: =IF(B35="","",B35) -> 46161
A36: Xænd-Thunderstrike | B36: 46161 | C36: 0.93055556 | D36: Greaves of the Bloodwarder | E36: 29950 | F36: item:29950::::::::70 | G36: 2nd BiS | H36: 0 | I36: WARRIOR | J36: Tempest Keep-25 Player | K36: High Astromancer Solarian | L36: Warbringer Greaves | M36: n/a | N36: 2 | O36: FALSE | P36: normal | Q36: Plate | R36: Legs | T36: Lilyasx-Thunderstrike | U36: =IF(B36="","",B36) -> 46161
A37: Xænd-Thunderstrike | B37: 46161 | C37: 0.93125 | D37: Plans: Red Belt of Battle | E37: 30322 | F37: item:30322::::::::70 | G37: 2nd BiS | H37: 1 | I37: WARRIOR | J37: Tempest Keep-25 Player | K37: SSC Trash | M37: n/a | N37: 2 | O37: FALSE | P37: normal | Q37: Blacksmithing | T37: Lilyasx-Thunderstrike | U37: =IF(B37="","",B37) -> 46161
A38: Spewspew-Thunderstrike | B38: 46161 | C38: 0.92986111 | D38: Pauldrons of the Vanquished Hero | E38: 30250 | F38: item:30250::::::::70 | G38: BiS | H38: 2 | I38: MAGE | J38: Tempest Keep-25 Player | K38: Void Reaver | L38: Pauldrons of the Aldor | M38: n/a | N38: 1 | O38: FALSE | P38: normal | Q38: Armor Token | T38: Lilyasx-Thunderstrike | U38: =IF(B38="","",B38) -> 46161
A39: Tuarendrood-Thunderstrike | B39: 46161 | C39: 0.90069444 | D39: Bark-Gloves of Ancient Wisdom | E39: 30029 | F39: item:30029::::::::70 | G39: Offspecc | H39: 0 | I39: DRUID | J39: Tempest Keep-25 Player | K39: TK Trash | L39: Mitts of the Treemender | M39: n/a | N39: 4 | O39: FALSE | P39: normal | Q39: Leather | R39: Hands | T39: Lilyasx-Thunderstrike | U39: =IF(B39="","",B39) -> 46161
A40: Tuarendrood-Thunderstrike | B40: 46161 | C40: 0.92986111 | D40: Pauldrons of the Vanquished Defender | E40: 30249 | F40: item:30249::::::::70 | G40: BiS | H40: 0 | I40: DRUID | J40: Tempest Keep-25 Player | K40: Void Reaver | L40: Shoulderguards of Malorne | M40: n/a | N40: 1 | O40: FALSE | P40: normal | Q40: Armor Token | T40: Lilyasx-Thunderstrike | U40: =IF(B40="","",B40) -> 46161
...

Sheet Player Lookup
A1: Player Loot Lookup | S1: Players (helper)
S2: {=_xlfn._xlws.SORT(_xlfn.UNIQUE(_xlfn._xlws.FILTER('Loot History'!A2:A1987,'Loot History'!A2:A1987<>"")))} -> Actitibe-Thunderstrike
A3: Select Player: | B3: Spewspew-Thunderstrike | S3: Aethrîa-Thunderstrike
S4: Alàén-Thunderstrike
A5: Item | B5: Instance | C5: Date | D5: Time | E5: Response | S5: Bigfutti-Thunderstrike
A6: {=IF($B$3="","← Select a player above",_xlfn._xlws.FILTER(_xlfn.HSTACK('Loot History'!D2:D176,'Loot History'!J2:J176,'Loot History'!B2:B176,'Loot History'!C2:C176,'Loot History'!G2:G176),'Loot History'!A2:A176=$B$3,"No items found for this player"))} -> Serpent-Coil Braid | B6: Coilfang: Serpentshrine Cavern-25 Player | C6: 46160 | D6: 0.90902778 | E6: BiS | S6: Desquite-Thunderstrike
A7: Pauldrons of the Vanquished Hero | B7: Tempest Keep-25 Player | C7: 46161 | D7: 0.92986111 | E7: BiS | S7: Fetzine-Thunderstrike
A8: Gloves of the Vanquished Hero | B8: Coilfang: Serpentshrine Cavern-25 Player | C8: 46163 | D8: 0.87986111 | E8: BiS | S8: Flieege-Thunderstrike
A9: Chestguard of the Vanquished Hero | B9: Tempest Keep-25 Player | C9: 46174 | D9: 0.84930556 | E9: BiS | S9: Gerdarogers-Thunderstrike
S10: Gorgohc-Thunderstrike
S11: Grathmok-Thunderstrike
S12: Heislbärt-Thunderstrike
S13: Hutro-Thunderstrike
S14: Keindaemon-Thunderstrike
S15: Klaaw-Thunderstrike
S16: Lilyasx-Thunderstrike
S17: Mahway-Thunderstrike
S18: Mardinez-Thunderstrike
S19: Mokrash-Thunderstrike
S20: Mommyfrieren-Thunderstrike
S21: Oßa-Thunderstrike
... S37: Zzou-Thunderstrike

Sheet Dashboard
A1: Loot Council Dashboard | D1: Items & Response by Player
D2: Player | E2: Total | F2: BiS | G2: 2nd BiS | H2: Upgrade | I2: Offspecc | J2: Passen | K2: Other | L2: Class | W2: Items by Boss | Z2: Items per Raid
A3: Total items awarded | B3: =COUNTA('Loot History'!D2:D987) -> 278 | D3: {=IFERROR(_xlfn._xlws.SORT(_xlfn.UNIQUE(_xlfn._xlws.FILTER('Loot History'!A2:A987,'Loot History'!A2:A987<>""))),"")} -> Actitibe-Thunderstrike | E3: =IF(D3="","",COUNTIF('Loot History'!$A:$A,D3)) -> 6 | F3: =IF(D3="","",COUNTIFS('Loot History'!$A:$A,D3,'Loot History'!$G:$G,"BiS")) -> 2 | G3: =IF(D3="","",COUNTIFS('Loot History'!$A:$A,D3,'Loot History'!$G:$G,"2nd BiS")) -> 1 | H3: =IF(D3="","",COUNTIFS('Loot History'!$A:$A,D3,'Loot History'!$G:$G,"Upgrade")) -> 3 | I3: =IF(D3="","",COUNTIFS('Loot History'!$A:$A,D3,'Loot History'!$G:$G,"Offspecc")) -> 0 | J3: =IF(D3="","",COUNTIFS('Loot History'!$A:$A,D3,'Loot History'!$G:$G,"Passen")) -> 0 | K3: =IF(D3="","",IFERROR(E3-F3-G3-H3-I3-J3,0)) -> 0 | L3: =IF(D3="","",IFERROR(INDEX('Loot History'!$I:$I,MATCH(D3,'Loot History'!$A:$A,0)),"")) -> SHAMAN | W3: Boss | X3: Items | Z3: Raid Date | AA3: Items | AB3: Instance
A4: Unique players | B4: {=SUMPRODUCT(('Loot History'!A2:A987<>"")/COUNTIF('Loot History'!A2:A987,'Loot History'!A2:A987&""))} -> 36 | D4: Aethrîa-Thunderstrike | E4: =IF(D4="","",COUNTIF('Loot History'!$A:$A,D4)) -> 9 | F4: =IF(D4="","",COUNTIFS('Loot History'!$A:$A,D4,'Loot History'!$G:$G,"BiS")) -> 7 | G4: =IF(D4="","",COUNTIFS('Loot History'!$A:$A,D4,'Loot History'!$G:$G,"2nd BiS")) -> 0 | H4: =IF(D4="","",COUNTIFS('Loot History'!$A:$A,D4,'Loot History'!$G:$G,"Upgrade")) -> 2 | I4: =IF(D4="","",COUNTIFS('Loot History'!$A:$A,D4,'Loot History'!$G:$G,"Offspecc")) -> 0 | J4: =IF(D4="","",COUNTIFS('Loot History'!$A:$A,D4,'Loot History'!$G:$G,"Passen")) -> 0 | K4: =IF(D4="","",IFERROR(E4-F4-G4-H4-I4-J4,0)) -> 0 | L4: =IF(D4="","",IFERROR(INDEX('Loot History'!$I:$I,MATCH(D4,'Loot History'!$A:$A,0)),"")) -> MAGE | W4: {=IFERROR(_xlfn._xlws.SORT(_xlfn.UNIQUE(_xlfn._xlws.FILTER('Loot History'!K2:K987,'Loot History'!K2:K987<>""))),"")} -> Al'ar | X4: =IF(W4="","",COUNTIF('Loot History'!$K:$K,W4)) -> 16 | Z4: {=IFERROR(_xlfn._xlws.SORT(_xlfn.UNIQUE(_xlfn._xlws.FILTER('Loot History'!B2:B987,'Loot History'!B2:B987<>""))),"")} -> 46160 | AA4: =IF(Z4="","",COUNTIF('Loot History'!$B:$B,Z4)) -> 26 | AB4: =IF(Z4="","",IFERROR(INDEX('Loot History'!$J:$J,MATCH(Z4,'Loot History'!$B:$B,0)),"")) -> Coilfang: Serpentshrine Cavern-25 Player
A5: Raid days | B5: {=SUMPRODUCT(('Loot History'!B2:B987<>"")/COUNTIF('Loot History'!B2:B987,'Loot History'!B2:B987&""))} -> 12 | D5: Alàén-Thunderstrike | E5: =IF(D5="","",COUNTIF('Loot History'!$A:$A,D5)) -> 13 | F5: =IF(D5="","",COUNTIFS('Loot History'!$A:$A,D5,'Loot History'!$G:$G,"BiS")) -> 3 | G5: =IF(D5="","",COUNTIFS('Loot History'!$A:$A,D5,'Loot History'!$G:$G,"2nd BiS")) -> 2 | H5: =IF(D5="","",COUNTIFS('Loot History'!$A:$A,D5,'Loot History'!$G:$G,"Upgrade")) -> 3 | I5: =IF(D5="","",COUNTIFS('Loot History'!$A:$A,D5,'Loot History'!$G:$G,"Offspecc")) -> 5 | J5: =IF(D5="","",COUNTIFS('Loot History'!$A:$A,D5,'Loot History'!$G:$G,"Passen")) -> 0 | K5: =IF(D5="","",IFERROR(E5-F5-G5-H5-I5-J5,0)) -> 0 | L5: =IF(D5="","",IFERROR(INDEX('Loot History'!$I:$I,MATCH(D5,'Loot History'!$A:$A,0)),"")) -> PALADIN | W5: Das Grauen aus der Tiefe | X5: =IF(W5="","",COUNTIF('Loot History'!$K:$K,W5)) -> 3 | Z5: 46161 | AA5: =IF(Z5="","",COUNTIF('Loot History'!$B:$B,Z5)) -> 14 | AB5: =IF(Z5="","",IFERROR(INDEX('Loot History'!$J:$J,MATCH(Z5,'Loot History'!$B:$B,0)),"")) -> Tempest Keep-25 Player
A6: First raid | B6: =_xlfn.MINIFS('Loot History'!B2:B987,'Loot History'!B2:B987,">0") -> 46160 | D6: Bigfutti-Thunderstrike | E6: =IF(D6="","",COUNTIF('Loot History'!$A:$A,D6)) -> 12 | F6: =IF(D6="","",COUNTIFS('Loot History'!$A:$A,D6,'Loot History'!$G:$G,"BiS")) -> 7 | G6: =IF(D6="","",COUNTIFS('Loot History'!$A:$A,D6,'Loot History'!$G:$G,"2nd BiS")) -> 0 | H6: =IF(D6="","",COUNTIFS('Loot History'!$A:$A,D6,'Loot History'!$G:$G,"Upgrade")) -> 1 | I6: =IF(D6="","",COUNTIFS('Loot History'!$A:$A,D6,'Loot History'!$G:$G,"Offspecc")) -> 4 | J6: =IF(D6="","",COUNTIFS('Loot History'!$A:$A,D6,'Loot History'!$G:$G,"Passen")) -> 0 | K6: =IF(D6="","",IFERROR(E6-F6-G6-H6-I6-J6,0)) -> 0 | L6: =IF(D6="","",IFERROR(INDEX('Loot History'!$I:$I,MATCH(D6,'Loot History'!$A:$A,0)),"")) -> PRIEST | W6: Fathom-Lord Karathress | X6: =IF(W6="","",COUNTIF('Loot History'!$K:$K,W6)) -> 20 | Z6: 46163 | AA6: =IF(Z6="","",COUNTIF('Loot History'!$B:$B,Z6)) -> 15 | AB6: =IF(Z6="","",IFERROR(INDEX('Loot History'!$J:$J,MATCH(Z6,'Loot History'!$B:$B,0)),"")) -> Coilfang: Serpentshrine Cavern-25 Player
A7: Last raid | B7: =MAX('Loot History'!B2:B987) -> 46202 | D7: Desquite-Thunderstrike | E7: =IF(D7="","",COUNTIF('Loot History'!$A:$A,D7)) -> 5 | F7: =IF(D7="","",COUNTIFS('Loot History'!$A:$A,D7,'Loot History'!$G:$G,"BiS")) -> 1 | G7: =IF(D7="","",COUNTIFS('Loot History'!$A:$A,D7,'Loot History'!$G:$G,"2nd BiS")) -> 0 | H7: =IF(D7="","",COUNTIFS('Loot History'!$A:$A,D7,'Loot History'!$G:$G,"Upgrade")) -> 0 | I7: =IF(D7="","",COUNTIFS('Loot History'!$A:$A,D7,'Loot History'!$G:$G,"Offspecc")) -> 2 | J7: =IF(D7="","",COUNTIFS('Loot History'!$A:$A,D7,'Loot History'!$G:$G,"Passen")) -> 0 | K7: =IF(D7="","",IFERROR(E7-F7-G7-H7-I7-J7,0)) -> 2 | L7: =IF(D7="","",IFERROR(INDEX('Loot History'!$I:$I,MATCH(D7,'Loot History'!$A:$A,0)),"")) -> PRIEST | W7: Gruul der Drachenschlächter | X7: =IF(W7="","",COUNTIF('Loot History'!$K:$K,W7)) -> 10 | Z7: 46167 | AA7: =IF(Z7="","",COUNTIF('Loot History'!$B:$B,Z7)) -> 17 | AB7: =IF(Z7="","",IFERROR(INDEX('Loot History'!$J:$J,MATCH(Z7,'Loot History'!$B:$B,0)),"")) -> Tempest Keep-25 Player
A8: Bosses killed (loot from) | B8: {=SUMPRODUCT(('Loot History'!K2:K987<>"")/COUNTIF('Loot History'!K2:K987,'Loot History'!K2:K987&""))} -> 28 | D8: Fetzine-Thunderstrike | E8: =IF(D8="","",COUNTIF('Loot History'!$A:$A,D8)) -> 13 | F8: =IF(D8="","",COUNTIFS('Loot History'!$A:$A,D8,'Loot History'!$G:$G,"BiS")) -> 7 | G8: =IF(D8="","",COUNTIFS('Loot History'!$A:$A,D8,'Loot History'!$G:$G,"2nd BiS")) -> 2 | H8: =IF(D8="","",COUNTIFS('Loot History'!$A:$A,D8,'Loot History'!$G:$G,"Upgrade")) -> 0 | I8: =IF(D8="","",COUNTIFS('Loot History'!$A:$A,D8,'Loot History'!$G:$G,"Offspecc")) -> 3 | J8: =IF(D8="","",COUNTIFS('Loot History'!$A:$A,D8,'Loot History'!$G:$G,"Passen")) -> 0 | K8: =IF(D8="","",IFERROR(E8-F8-G8-H8-I8-J8,0)) -> 1 | L8: =IF(D8="","",IFERROR(INDEX('Loot History'!$I:$I,MATCH(D8,'Loot History'!$A:$A,0)),"")) -> HUNTER | W8: Gruul the Dragonkiller | X8: =IF(W8="","",COUNTIF('Loot History'!$K:$K,W8)) -> 10 | Z8: 46170 | AA8: =IF(Z8="","",COUNTIF('Loot History'!$B:$B,Z8)) -> 38 | AB8: =IF(Z8="","",IFERROR(INDEX('Loot History'!$J:$J,MATCH(Z8,'Loot History'!$B:$B,0)),"")) -> Coilfang: Serpentshrine Cavern-25 Player
D9: Flieege-Thunderstrike | E9: =IF(D9="","",COUNTIF('Loot History'!$A:$A,D9)) -> 4 | F9: =IF(D9="","",COUNTIFS('Loot History'!$A:$A,D9,'Loot History'!$G:$G,"BiS")) -> 4 | G9: =IF(D9="","",COUNTIFS('Loot History'!$A:$A,D9,'Loot History'!$G:$G,"2nd BiS")) -> 0 | H9: =IF(D9="","",COUNTIFS('Loot History'!$A:$A,D9,'Loot History'!$G:$G,"Upgrade")) -> 0 | I9: =IF(D9="","",COUNTIFS('Loot History'!$A:$A,D9,'Loot History'!$G:$G,"Offspecc")) -> 0 | J9: =IF(D9="","",COUNTIFS('Loot History'!$A:$A,D9,'Loot History'!$G:$G,"Passen")) -> 0 | K9: =IF(D9="","",IFERROR(E9-F9-G9-H9-I9-J9,0)) -> 0 | L9: =IF(D9="","",IFERROR(INDEX('Loot History'!$I:$I,MATCH(D9,'Loot History'!$A:$A,0)),"")) -> WARLOCK | W9: High Astromancer Solarian | X9: =IF(W9="","",COUNTIF('Loot History'!$K:$K,W9)) -> 16 | Z9: 46174 | AA9: =IF(Z9="","",COUNTIF('Loot History'!$B:$B,Z9)) -> 13 | AB9: =IF(Z9="","",IFERROR(INDEX('Loot History'!$J:$J,MATCH(Z9,'Loot History'!$B:$B,0)),"")) -> Tempest Keep-25 Player
D10: Gerdarogers-Thunderstrike | E10: =IF(D10="","",COUNTIF('Loot History'!$A:$A,D10)) -> 6 | F10: =IF(D10="","",COUNTIFS('Loot History'!$A:$A,D10,'Loot History'!$G:$G,"BiS")) -> 3 | G10: =IF(D10="","",COUNTIFS('Loot History'!$A:$A,D10,'Loot History'!$G:$G,"2nd BiS")) -> 1 | H10: =IF(D10="","",COUNTIFS('Loot History'!$A:$A,D10,'Loot History'!$G:$G,"Upgrade")) -> 1 | I10: =IF(D10="","",COUNTIFS('Loot History'!$A:$A,D10,'Loot History'!$G:$G,"Offspecc")) -> 1 | J10: =IF(D10="","",COUNTIFS('Loot History'!$A:$A,D10,'Loot History'!$G:$G,"Passen")) -> 0 | K10: =IF(D10="","",IFERROR(E10-F10-G10-H10-I10-J10,0)) -> 0 | L10: =IF(D10="","",IFERROR(INDEX('Loot History'!$I:$I,MATCH(D10,'Loot History'!$A:$A,0)),"")) -> WARLOCK | W10: High King Maulgar | X10: =IF(W10="","",COUNTIF('Loot History'!$K:$K,W10)) -> 8 | Z10: 46177 | AA10: =IF(Z10="","",COUNTIF('Loot History'!$B:$B,Z10)) -> 22 | AB10: =IF(Z10="","",IFERROR(INDEX('Loot History'!$J:$J,MATCH(Z10,'Loot History'!$B:$B,0)),"")) -> Coilfang: Serpentshrine Cavern-25 Player
D11: Gorgohc-Thunderstrike | E11: =IF(D11="","",COUNTIF('Loot History'!$A:$A,D11)) -> 4 | F11: =IF(D11="","",COUNTIFS('Loot History'!$A:$A,D11,'Loot History'!$G:$G,"BiS")) -> 0 | G11: =IF(D11="","",COUNTIFS('Loot History'!$A:$A,D11,'Loot History'!$G:$G,"2nd BiS")) -> 0 | H11: =IF(D11="","",COUNTIFS('Loot History'!$A:$A,D11,'Loot History'!$G:$G,"Upgrade")) -> 4 | I11: =IF(D11="","",COUNTIFS('Loot History'!$A:$A,D11,'Loot History'!$G:$G,"Offspecc")) -> 0 | J11: =IF(D11="","",COUNTIFS('Loot History'!$A:$A,D11,'Loot History'!$G:$G,"Passen")) -> 0 | K11: =IF(D11="","",IFERROR(E11-F11-G11-H11-I11-J11,0)) -> 0 | L11: =IF(D11="","",IFERROR(INDEX('Loot History'!$I:$I,MATCH(D11,'Loot History'!$A:$A,0)),"")) -> PALADIN | W11: Hochastromantin Solarian | X11: =IF(W11="","",COUNTIF('Loot History'!$K:$K,W11)) -> 3 | Z11: 46181 | AA11: =IF(Z11="","",COUNTIF('Loot History'!$B:$B,Z11)) -> 27 | AB11: =IF(Z11="","",IFERROR(INDEX('Loot History'!$J:$J,MATCH(Z11,'Loot History'!$B:$B,0)),"")) -> Tempest Keep-25 Player
D12: Grathmok-Thunderstrike | E12: =IF(D12="","",COUNTIF('Loot History'!$A:$A,D12)) -> 6 | F12: =IF(D12="","",COUNTIFS('Loot History'!$A:$A,D12,'Loot History'!$G:$G,"BiS")) -> 4 | G12: =IF(D12="","",COUNTIFS('Loot History'!$A:$A,D12,'Loot History'!$G:$G,"2nd BiS")) -> 0 | H12: =IF(D12="","",COUNTIFS('Loot History'!$A:$A,D12,'Loot History'!$G:$G,"Upgrade")) -> 1 | I12: =IF(D12="","",COUNTIFS('Loot History'!$A:$A,D12,'Loot History'!$G:$G,"Offspecc")) -> 1 | J12: =IF(D12="","",COUNTIFS('Loot History'!$A:$A,D12,'Loot History'!$G:$G,"Passen")) -> 0 | K12: =IF(D12="","",IFERROR(E12-F12-G12-H12-I12-J12,0)) -> 0 | L12: =IF(D12="","",IFERROR(INDEX('Loot History'!$I:$I,MATCH(D12,'Loot History'!$A:$A,0)),"")) -> SHAMAN | W12: Hochkönig Maulgar | X12: =IF(W12="","",COUNTIF('Loot History'!$K:$K,W12)) -> 2 | Z12: 46188 | AA12: =IF(Z12="","",COUNTIF('Loot History'!$B:$B,Z12)) -> 38 | AB12: =IF(Z12="","",IFERROR(INDEX('Loot History'!$J:$J,MATCH(Z12,'Loot History'!$B:$B,0)),"")) -> Coilfang: Serpentshrine Cavern-25 Player
D13: Heislbärt-Thunderstrike | E13: =IF(D13="","",COUNTIF('Loot History'!$A:$A,D13)) -> 7 | F13: =IF(D13="","",COUNTIFS('Loot History'!$A:$A,D13,'Loot History'!$G:$G,"BiS")) -> 6 | G13: =IF(D13="","",COUNTIFS('Loot History'!$A:$A,D13,'Loot History'!$G:$G,"2nd BiS")) -> 0 | H13: =IF(D13="","",COUNTIFS('Loot History'!$A:$A,D13,'Loot History'!$G:$G,"Upgrade")) -> 0 | I13: =IF(D13="","",COUNTIFS('Loot History'!$A:$A,D13,'Loot History'!$G:$G,"Offspecc")) -> 0 | J13: =IF(D13="","",COUNTIFS('Loot History'!$A:$A,D13,'Loot History'!$G:$G,"Passen")) -> 0 | K13: =IF(D13="","",IFERROR(E13-F13-G13-H13-I13-J13,0)) -> 1 | L13: =IF(D13="","",IFERROR(INDEX('Loot History'!$I:$I,MATCH(D13,'Loot History'!$A:$A,0)),"")) -> DRUID | W13: Hydross der Unstete | X13: =IF(W13="","",COUNTIF('Loot History'!$K:$K,W13)) -> 3 | Z13: 46195 | AA13: =IF(Z13="","",COUNTIF('Loot History'!$B:$B,Z13)) -> 21 | AB13: =IF(Z13="","",IFERROR(INDEX('Loot History'!$J:$J,MATCH(Z13,'Loot History'!$B:$B,0)),"")) -> Tempest Keep-25 Player
D14: Hutro-Thunderstrike | E14: =IF(D14="","",COUNTIF('Loot History'!$A:$A,D14)) -> 6 | F14: =IF(D14="","",COUNTIFS('Loot History'!$A:$A,D14,'Loot History'!$G:$G,"BiS")) -> 5 | G14: =IF(D14="","",COUNTIFS('Loot History'!$A:$A,D14,'Loot History'!$G:$G,"2nd BiS")) -> 0 | H14: =IF(D14="","",COUNTIFS('Loot History'!$A:$A,D14,'Loot History'!$G:$G,"Upgrade")) -> 0 | I14: =IF(D14="","",COUNTIFS('Loot History'!$A:$A,D14,'Loot History'!$G:$G,"Offspecc")) -> 1 | J14: =IF(D14="","",COUNTIFS('Loot History'!$A:$A,D14,'Loot History'!$G:$G,"Passen")) -> 0 | K14: =IF(D14="","",IFERROR(E14-F14-G14-H14-I14-J14,0)) -> 0 | L14: =IF(D14="","",IFERROR(INDEX('Loot History'!$I:$I,MATCH(D14,'Loot History'!$A:$A,0)),"")) -> ROGUE | W14: Hydross the Unstable | X14: =IF(W14="","",COUNTIF('Loot History'!$K:$K,W14)) -> 11 | Z14: 46198 | AA14: =IF(Z14="","",COUNTIF('Loot History'!$B:$B,Z14)) -> 22 | AB14: =IF(Z14="","",IFERROR(INDEX('Loot History'!$J:$J,MATCH(Z14,'Loot History'!$B:$B,0)),"")) -> Coilfang: Serpentshrine Cavern-25 Player
D15: Keindaemon-Thunderstrike | E15: =IF(D15="","",COUNTIF('Loot History'!$A:$A,D15)) -> 13 | F15: =IF(D15="","",COUNTIFS('Loot History'!$A:$A,D15,'Loot History'!$G:$G,"BiS")) -> 8 | G15: =IF(D15="","",COUNTIFS('Loot History'!$A:$A,D15,'Loot History'!$G:$G,"2nd BiS")) -> 1 | H15: =IF(D15="","",COUNTIFS('Loot History'!$A:$A,D15,'Loot History'!$G:$G,"Upgrade")) -> 2 | I15: =IF(D15="","",COUNTIFS('Loot History'!$A:$A,D15,'Loot History'!$G:$G,"Offspecc")) -> 2 | J15: =IF(D15="","",COUNTIFS('Loot History'!$A:$A,D15,'Loot History'!$G:$G,"Passen")) -> 0 | K15: =IF(D15="","",IFERROR(E15-F15-G15-H15-I15-J15,0)) -> 0 | L15: =IF(D15="","",IFERROR(INDEX('Loot History'!$I:$I,MATCH(D15,'Loot History'!$A:$A,0)),"")) -> DRUID | W15: Kael'thas Sonnenwanderer | X15: =IF(W15="","",COUNTIF('Loot History'!$K:$K,W15)) -> 12 | Z15: 46202 | AA15: =IF(Z15="","",COUNTIF('Loot History'!$B:$B,Z15)) -> 25 | AB15: =IF(Z15="","",IFERROR(INDEX('Loot History'!$J:$J,MATCH(Z15,'Loot History'!$B:$B,0)),"")) -> Gruuls Lair-25 Player
D16: Klaaw-Thunderstrike | E16: =IF(D16="","",COUNTIF('Loot History'!$A:$A,D16)) -> 7 | F16: =IF(D16="","",COUNTIFS('Loot History'!$A:$A,D16,'Loot History'!$G:$G,"BiS")) -> 4 | G16: =IF(D16="","",COUNTIFS('Loot History'!$A:$A,D16,'Loot History'!$G:$G,"2nd BiS")) -> 2 | H16: =IF(D16="","",COUNTIFS('Loot History'!$A:$A,D16,'Loot History'!$G:$G,"Upgrade")) -> 1 | I16: =IF(D16="","",COUNTIFS('Loot History'!$A:$A,D16,'Loot History'!$G:$G,"Offspecc")) -> 0 | J16: =IF(D16="","",COUNTIFS('Loot History'!$A:$A,D16,'Loot History'!$G:$G,"Passen")) -> 0 | K16: =IF(D16="","",IFERROR(E16-F16-G16-H16-I16-J16,0)) -> 0 | L16: =IF(D16="","",IFERROR(INDEX('Loot History'!$I:$I,MATCH(D16,'Loot History'!$A:$A,0)),"")) -> HUNTER | W16: Kael'thas Sunstrider | X16: =IF(W16="","",COUNTIF('Loot History'!$K:$K,W16)) -> 22 | AA16: =IF(Z16="","",COUNTIF('Loot History'!$B:$B,Z16)) | AB16: =IF(Z16="","",IFERROR(INDEX('Loot History'!$J:$J,MATCH(Z16,'Loot History'!$B:$B,0)),""))
D17: Lilyasx-Thunderstrike | E17: =IF(D17="","",COUNTIF('Loot History'!$A:$A,D17)) -> 2 | F17: =IF(D17="","",COUNTIFS('Loot History'!$A:$A,D17,'Loot History'!$G:$G,"BiS")) -> 0 | G17: =IF(D17="","",COUNTIFS('Loot History'!$A:$A,D17,'Loot History'!$G:$G,"2nd BiS")) -> 1 | H17: =IF(D17="","",COUNTIFS('Loot History'!$A:$A,D17,'Loot History'!$G:$G,"Upgrade")) -> 1 | I17: =IF(D17="","",COUNTIFS('Loot History'!$A:$A,D17,'Loot History'!$G:$G,"Offspecc")) -> 0 | J17: =IF(D17="","",COUNTIFS('Loot History'!$A:$A,D17,'Loot History'!$G:$G,"Passen")) -> 0 | K17: =IF(D17="","",IFERROR(E17-F17-G17-H17-I17-J17,0)) -> 0 | L17: =IF(D17="","",IFERROR(INDEX('Loot History'!$I:$I,MATCH(D17,'Loot History'!$A:$A,0)),"")) -> DRUID | W17: Lady Vashj | X17: =IF(W17="","",COUNTIF('Loot History'!$K:$K,W17)) -> 23 | AA17: =IF(Z17="","",COUNTIF('Loot History'!$B:$B,Z17)) | AB17: =IF(Z17="","",IFERROR(INDEX('Loot History'!$J:$J,MATCH(Z17,'Loot History'!$B:$B,0)),""))
D18: Mahway-Thunderstrike | E18: =IF(D18="","",COUNTIF('Loot History'!$A:$A,D18)) -> 6 | F18: =IF(D18="","",COUNTIFS('Loot History'!$A:$A,D18,'Loot History'!$G:$G,"BiS")) -> 1 | G18: =IF(D18="","",COUNTIFS('Loot History'!$A:$A,D18,'Loot History'!$G:$G,"2nd BiS")) -> 3 | H18: =IF(D18="","",COUNTIFS('Loot History'!$A:$A,D18,'Loot History'!$G:$G,"Upgrade")) -> 2 | I18: =IF(D18="","",COUNTIFS('Loot History'!$A:$A,D18,'Loot History'!$G:$G,"Offspecc")) -> 0 | J18: =IF(D18="","",COUNTIFS('Loot History'!$A:$A,D18,'Loot History'!$G:$G,"Passen")) -> 0 | K18: =IF(D18="","",IFERROR(E18-F18-G18-H18-I18-J18,0)) -> 0 | L18: =IF(D18="","",IFERROR(INDEX('Loot History'!$I:$I,MATCH(D18,'Loot History'!$A:$A,0)),"")) -> SHAMAN | W18: Lady Vashj — name unverified | X18: =IF(W18="","",COUNTIF('Loot History'!$K:$K,W18)) -> 1 | AA18: =IF(Z18="","",COUNTIF('Loot History'!$B:$B,Z18)) | AB18: =IF(Z18="","",IFERROR(INDEX('Loot History'!$J:$J,MATCH(Z18,'Loot History'!$B:$B,0)),""))
D19: Mardinez-Thunderstrike | E19: =IF(D19="","",COUNTIF('Loot History'!$A:$A,D19)) -> 9 | F19: =IF(D19="","",COUNTIFS('Loot History'!$A:$A,D19,'Loot History'!$G:$G,"BiS")) -> 7 | G19: =IF(D19="","",COUNTIFS('Loot History'!$A:$A,D19,'Loot History'!$G:$G,"2nd BiS")) -> 2 | H19: =IF(D19="","",COUNTIFS('Loot History'!$A:$A,D19,'Loot History'!$G:$G,"Upgrade")) -> 0 | I19: =IF(D19="","",COUNTIFS('Loot History'!$A:$A,D19,'Loot History'!$G:$G,"Offspecc")) -> 0 | J19: =IF(D19="","",COUNTIFS('Loot History'!$A:$A,D19,'Loot History'!$G:$G,"Passen")) -> 0 | K19: =IF(D19="","",IFERROR(E19-F19-G19-H19-I19-J19,0)) -> 0 | L19: =IF(D19="","",IFERROR(INDEX('Loot History'!$I:$I,MATCH(D19,'Loot History'!$A:$A,0)),"")) -> PRIEST | W19: Leerhäscher | X19: =IF(W19="","",COUNTIF('Loot History'!$K:$K,W19)) -> 9 | AA19: =IF(Z19="","",COUNTIF('Loot History'!$B:$B,Z19)) | AB19: =IF(Z19="","",IFERROR(INDEX('Loot History'!$J:$J,MATCH(Z19,'Loot History'!$B:$B,0)),""))
D20: Mokrash-Thunderstrike | E20: =IF(D20="","",COUNTIF('Loot History'!$A:$A,D20)) -> 10 | F20: =IF(D20="","",COUNTIFS('Loot History'!$A:$A,D20,'Loot History'!$G:$G,"BiS")) -> 7 | G20: =IF(D20="","",COUNTIFS('Loot History'!$A:$A,D20,'Loot History'!$G:$G,"2nd BiS")) -> 0 | H20: =IF(D20="","",COUNTIFS('Loot History'!$A:$A,D20,'Loot History'!$G:$G,"Upgrade")) -> 1 | I20: =IF(D20="","",COUNTIFS('Loot History'!$A:$A,D20,'Loot History'!$G:$G,"Offspecc")) -> 1 | J20: =IF(D20="","",COUNTIFS('Loot History'!$A:$A,D20,'Loot History'!$G:$G,"Passen")) -> 0 | K20: =IF(D20="","",IFERROR(E20-F20-G20-H20-I20-J20,0)) -> 1 | L20: =IF(D20="","",IFERROR(INDEX('Loot History'!$I:$I,MATCH(D20,'Loot History'!$A:$A,0)),"")) -> WARRIOR | W20: Leotheras der Blinde | X20: =IF(W20="","",COUNTIF('Loot History'!$K:$K,W20)) -> 4 | AA20: =IF(Z20="","",COUNTIF('Loot History'!$B:$B,Z20)) | AB20: =IF(Z20="","",IFERROR(INDEX('Loot History'!$J:$J,MATCH(Z20,'Loot History'!$B:$B,0)),""))
D21: Mommyfrieren-Thunderstrike | E21: =IF(D21="","",COUNTIF('Loot History'!$A:$A,D21)) -> 5 | F21: =IF(D21="","",COUNTIFS('Loot History'!$A:$A,D21,'Loot History'!$G:$G,"BiS")) -> 4 | G21: =IF(D21="","",COUNTIFS('Loot History'!$A:$A,D21,'Loot History'!$G:$G,"2nd BiS")) -> 0 | H21: =IF(D21="","",COUNTIFS('Loot History'!$A:$A,D21,'Loot History'!$G:$G,"Upgrade")) -> 0 | I21: =IF(D21="","",COUNTIFS('Loot History'!$A:$A,D21,'Loot History'!$G:$G,"Offspecc")) -> 1 | J21: =IF(D21="","",COUNTIFS('Loot History'!$A:$A,D21,'Loot History'!$G:$G,"Passen")) -> 0 | K21: =IF(D21="","",IFERROR(E21-F21-G21-H21-I21-J21,0)) -> 0 | L21: =IF(D21="","",IFERROR(INDEX('Loot History'!$I:$I,MATCH(D21,'Loot History'!$A:$A,0)),"")) -> WARLOCK | W21: Leotheras the Blind | X21: =IF(W21="","",COUNTIF('Loot History'!$K:$K,W21)) -> 14 | AA21: =IF(Z21="","",COUNTIF('Loot History'!$B:$B,Z21)) | AB21: =IF(Z21="","",IFERROR(INDEX('Loot History'!$J:$J,MATCH(Z21,'Loot History'!$B:$B,0)),""))
D22: Oßa-Thunderstrike | E22: =IF(D22="","",COUNTIF('Loot History'!$A:$A,D22)) -> 9 | F22: =IF(D22="","",COUNTIFS('Loot History'!$A:$A,D22,'Loot History'!$G:$G,"BiS")) -> 5 | G22: =IF(D22="","",COUNTIFS('Loot History'!$A:$A,D22,'Loot History'!$G:$G,"2nd BiS")) -> 0 | H22: =IF(D22="","",COUNTIFS('Loot History'!$A:$A,D22,'Loot History'!$G:$G,"Upgrade")) -> 2 | I22: =IF(D22="","",COUNTIFS('Loot History'!$A:$A,D22,'Loot History'!$G:$G,"Offspecc")) -> 1 | J22: =IF(D22="","",COUNTIFS('Loot History'!$A:$A,D22,'Loot History'!$G:$G,"Passen")) -> 0 | K22: =IF(D22="","",IFERROR(E22-F22-G22-H22-I22-J22,0)) -> 1 | L22: =IF(D22="","",IFERROR(INDEX('Loot History'!$I:$I,MATCH(D22,'Loot History'!$A:$A,0)),"")) -> SHAMAN | W22: Magtheridon | AA22: =IF(Z22="","",COUNTIF('Loot History'!$B:$B,Z22)) | AB22: =IF(Z22="","",IFERROR(INDEX('Loot History'!$J:$J,MATCH(Z22,'Loot History'!$B:$B,0)),""))
D23: Razoga-Thunderstrike | E23: =IF(D23="","",COUNTIF('Loot History'!$A:$A,D23)) -> 1 | F23: =IF(D23="","",COUNTIFS('Loot History'!$A:$A,D23,'Loot History'!$G:$G,"BiS")) -> 1 | G23: =IF(D23="","",COUNTIFS('Loot History'!$A:$A,D23,'Loot History'!$G:$G,"2nd BiS")) -> 0 | H23: =IF(D23="","",COUNTIFS('Loot History'!$A:$A,D23,'Loot History'!$G:$G,"Upgrade")) -> 0 | I23: =IF(D23="","",COUNTIFS('Loot History'!$A:$A,D23,'Loot History'!$G:$G,"Offspecc")) -> 0 | J23: =IF(D23="","",COUNTIFS('Loot History'!$A:$A,D23,'Loot History'!$G:$G,"Passen")) -> 0 | K23: =IF(D23="","",IFERROR(E23-F23-G23-H23-I23-J23,0)) -> 0 | L23: =IF(D23="","",IFERROR(INDEX('Loot History'!$I:$I,MATCH(D23,'Loot History'!$A:$A,0)),"")) -> SHAMAN | W23: Morogrim Gezeitenwandler | AA23: =IF(Z23="","",COUNTIF('Loot History'!$B:$B,Z23)) | AB23: =IF(Z23="","",IFERROR(INDEX('Loot History'!$J:$J,MATCH(Z23,'Loot History'!$B:$B,0)),""))
D24: Reazø-Thunderstrike | E24: =IF(D24="","",COUNTIF('Loot History'!$A:$A,D24)) -> 5 | F24: =IF(D24="","",COUNTIFS('Loot History'!$A:$A,D24,'Loot History'!$G:$G,"BiS")) -> 3 | G24: =IF(D24="","",COUNTIFS('Loot History'!$A:$A,D24,'Loot History'!$G:$G,"2nd BiS")) -> 0 | H24: =IF(D24="","",COUNTIFS('Loot History'!$A:$A,D24,'Loot History'!$G:$G,"Upgrade")) -> 0 | I24: =IF(D24="","",COUNTIFS('Loot History'!$A:$A,D24,'Loot History'!$G:$G,"Offspecc")) -> 2 | J24: =IF(D24="","",COUNTIFS('Loot History'!$A:$A,D24,'Loot History'!$G:$G,"Passen")) -> 0 | K24: =IF(D24="","",IFERROR(E24-F24-G24-H24-I24-J24,0)) -> 0 | L24: =IF(D24="","",IFERROR(INDEX('Loot History'!$I:$I,MATCH(D24,'Loot History'!$A:$A,0)),"")) -> DRUID | W24: Morogrim Tidewalker | AA24: =IF(Z24="","",COUNTIF('Loot History'!$B:$B,Z24)) | AB24: =IF(Z24="","",IFERROR(INDEX('Loot History'!$J:$J,MATCH(Z24,'Loot History'!$B:$B,0)),""))
D25: Reezø-Thunderstrike | E25: =IF(D25="","",COUNTIF('Loot History'!$A:$A,D25)) -> 15 | F25: =IF(D25="","",COUNTIFS('Loot History'!$A:$A,D25,'Loot History'!$G:$G,"BiS")) -> 6 | G25: =IF(D25="","",COUNTIFS('Loot History'!$A:$A,D25,'Loot History'!$G:$G,"2nd BiS")) -> 4 | H25: =IF(D25="","",COUNTIFS('Loot History'!$A:$A,D25,'Loot History'!$G:$G,"Upgrade")) -> 4 | I25: =IF(D25="","",COUNTIFS('Loot History'!$A:$A,D25,'Loot History'!$G:$G,"Offspecc")) -> 1 | J25: =IF(D25="","",COUNTIFS('Loot History'!$A:$A,D25,'Loot History'!$G:$G,"Passen")) -> 0 | K25: =IF(D25="","",IFERROR(E25-F25-G25-H25-I25-J25,0)) -> 0 | L25: =IF(D25="","",IFERROR(INDEX('Loot History'!$I:$I,MATCH(D25,'Loot History'!$A:$A,0)),"")) -> PALADIN | W25: SSC / TK Trash | AA25: =IF(Z25="","",COUNTIF('Loot History'!$B:$B,Z25)) | AB25: =IF(Z25="","",IFERROR(INDEX('Loot History'!$J:$J,MATCH(Z25,'Loot History'!$B:$B,0)),""))
D26: Ribsz-Thunderstrike | E26: =IF(D26="","",COUNTIF('Loot History'!$A:$A,D26)) -> 6 | F26: =IF(D26="","",COUNTIFS('Loot History'!$A:$A,D26,'Loot History'!$G:$G,"BiS")) -> 2 | G26: =IF(D26="","",COUNTIFS('Loot History'!$A:$A,D26,'Loot History'!$G:$G,"2nd BiS")) -> 4 | H26: =IF(D26="","",COUNTIFS('Loot History'!$A:$A,D26,'Loot History'!$G:$G,"Upgrade")) -> 0 | I26: =IF(D26="","",COUNTIFS('Loot History'!$A:$A,D26,'Loot History'!$G:$G,"Offspecc")) -> 0 | J26: =IF(D26="","",COUNTIFS('Loot History'!$A:$A,D26,'Loot History'!$G:$G,"Passen")) -> 0 | K26: =IF(D26="","",IFERROR(E26-F26-G26-H26-I26-J26,0)) -> 0 | L26: =IF(D26="","",IFERROR(INDEX('Loot History'!$I:$I,MATCH(D26,'Loot History'!$A:$A,0)),"")) -> MAGE | W26: SSC Trash | AA26: =IF(Z26="","",COUNTIF('Loot History'!$B:$B,Z26)) | AB26: =IF(Z26="","",IFERROR(INDEX('Loot History'!$J:$J,MATCH(Z26,'Loot History'!$B:$B,0)),""))
D27: Sanderon-Thunderstrike | E27: =IF(D27="","",COUNTIF('Loot History'!$A:$A,D27)) -> 2 | F27: =IF(D27="","",COUNTIFS('Loot History'!$A:$A,D27,'Loot History'!$G:$G,"BiS")) -> 2 | G27: =IF(D27="","",COUNTIFS('Loot History'!$A:$A,D27,'Loot History'!$G:$G,"2nd BiS")) -> 0 | H27: =IF(D27="","",COUNTIFS('Loot History'!$A:$A,D27,'Loot History'!$G:$G,"Upgrade")) -> 0 | I27: =IF(D27="","",COUNTIFS('Loot History'!$A:$A,D27,'Loot History'!$G:$G,"Offspecc")) -> 0 | J27: =IF(D27="","",COUNTIFS('Loot History'!$A:$A,D27,'Loot History'!$G:$G,"Passen")) -> 0 | K27: =IF(D27="","",IFERROR(E27-F27-G27-H27-I27-J27,0)) -> 0 | L27: =IF(D27="","",IFERROR(INDEX('Loot History'!$I:$I,MATCH(D27,'Loot History'!$A:$A,0)),"")) -> PRIEST | W27: The Lurker Below | AA27: =IF(Z27="","",COUNTIF('Loot History'!$B:$B,Z27)) | AB27: =IF(Z27="","",IFERROR(INDEX('Loot History'!$J:$J,MATCH(Z27,'Loot History'!$B:$B,0)),""))
D28: Shreklich-Thunderstrike | E28: =IF(D28="","",COUNTIF('Loot History'!$A:$A,D28)) -> 4 | F28: =IF(D28="","",COUNTIFS('Loot History'!$A:$A,D28,'Loot History'!$G:$G,"BiS")) -> 2 | G28: =IF(D28="","",COUNTIFS('Loot History'!$A:$A,D28,'Loot History'!$G:$G,"2nd BiS")) -> 0 | H28: =IF(D28="","",COUNTIFS('Loot History'!$A:$A,D28,'Loot History'!$G:$G,"Upgrade")) -> 1 | I28: =IF(D28="","",COUNTIFS('Loot History'!$A:$A,D28,'Loot History'!$G:$G,"Offspecc")) -> 1 | J28: =IF(D28="","",COUNTIFS('Loot History'!$A:$A,D28,'Loot History'!$G:$G,"Passen")) -> 0 | K28: =IF(D28="","",IFERROR(E28-F28-G28-H28-I28-J28,0)) -> 0 | L28: =IF(D28="","",IFERROR(INDEX('Loot History'!$I:$I,MATCH(D28,'Loot History'!$A:$A,0)),"")) -> WARRIOR | W28: Tiefenlord Karathress | AA28: =IF(Z28="","",COUNTIF('Loot History'!$B:$B,Z28)) | AB28: =IF(Z28="","",IFERROR(INDEX('Loot History'!$J:$J,MATCH(Z28,'Loot History'!$B:$B,0)),""))
D29: Spewspew-Thunderstrike | E29: =IF(D29="","",COUNTIF('Loot History'!$A:$A,D29)) -> 6 | F29: =IF(D29="","",COUNTIFS('Loot History'!$A:$A,D29,'Loot History'!$G:$G,"BiS")) -> 6 | G29: =IF(D29="","",COUNTIFS('Loot History'!$A:$A,D29,'Loot History'!$G:$G,"2nd BiS")) -> 0 | H29: =IF(D29="","",COUNTIFS('Loot History'!$A:$A,D29,'Loot History'!$G:$G,"Upgrade")) -> 0 | I29: =IF(D29="","",COUNTIFS('Loot History'!$A:$A,D29,'Loot History'!$G:$G,"Offspecc")) -> 0 | J29: =IF(D29="","",COUNTIFS('Loot History'!$A:$A,D29,'Loot History'!$G:$G,"Passen")) -> 0 | K29: =IF(D29="","",IFERROR(E29-F29-G29-H29-I29-J29,0)) -> 0 | L29: =IF(D29="","",IFERROR(INDEX('Loot History'!$I:$I,MATCH(D29,'Loot History'!$A:$A,0)),"")) -> MAGE | W29: TK Trash | AA29: =IF(Z29="","",COUNTIF('Loot History'!$B:$B,Z29)) | AB29: =IF(Z29="","",IFERROR(INDEX('Loot History'!$J:$J,MATCH(Z29,'Loot History'!$B:$B,0)),""))
D30: Supmyaeth-Thunderstrike | E30: =IF(D30="","",COUNTIF('Loot History'!$A:$A,D30)) -> 9 | F30: =IF(D30="","",COUNTIFS('Loot History'!$A:$A,D30,'Loot History'!$G:$G,"BiS")) -> 5 | G30: =IF(D30="","",COUNTIFS('Loot History'!$A:$A,D30,'Loot History'!$G:$G,"2nd BiS")) -> 1 | H30: =IF(D30="","",COUNTIFS('Loot History'!$A:$A,D30,'Loot History'!$G:$G,"Upgrade")) -> 2 | I30: =IF(D30="","",COUNTIFS('Loot History'!$A:$A,D30,'Loot History'!$G:$G,"Offspecc")) -> 1 | J30: =IF(D30="","",COUNTIFS('Loot History'!$A:$A,D30,'Loot History'!$G:$G,"Passen")) -> 0 | K30: =IF(D30="","",IFERROR(E30-F30-G30-H30-I30-J30,0)) -> 0 | L30: =IF(D30="","",IFERROR(INDEX('Loot History'!$I:$I,MATCH(D30,'Loot History'!$A:$A,0)),"")) -> SHAMAN | W30: Unbekannt | AA30: =IF(Z30="","",COUNTIF('Loot History'!$B:$B,Z30)) | AB30: =IF(Z30="","",IFERROR(INDEX('Loot History'!$J:$J,MATCH(Z30,'Loot History'!$B:$B,0)),""))
D31: Tastycake-Thunderstrike | E31: =IF(D31="","",COUNTIF('Loot History'!$A:$A,D31)) -> 6 | F31: =IF(D31="","",COUNTIFS('Loot History'!$A:$A,D31,'Loot History'!$G:$G,"BiS")) -> 3 | G31: =IF(D31="","",COUNTIFS('Loot History'!$A:$A,D31,'Loot History'!$G:$G,"2nd BiS")) -> 1 | H31: =IF(D31="","",COUNTIFS('Loot History'!$A:$A,D31,'Loot History'!$G:$G,"Upgrade")) -> 2 | I31: =IF(D31="","",COUNTIFS('Loot History'!$A:$A,D31,'Loot History'!$G:$G,"Offspecc")) -> 0 | J31: =IF(D31="","",COUNTIFS('Loot History'!$A:$A,D31,'Loot History'!$G:$G,"Passen")) -> 0 | K31: =IF(D31="","",IFERROR(E31-F31-G31-H31-I31-J31,0)) -> 0 | L31: =IF(D31="","",IFERROR(INDEX('Loot History'!$I:$I,MATCH(D31,'Loot History'!$A:$A,0)),"")) -> MAGE | W31: Void Reaver | AA31: =IF(Z31="","",COUNTIF('Loot History'!$B:$B,Z31)) | AB31: =IF(Z31="","",IFERROR(INDEX('Loot History'!$J:$J,MATCH(Z31,'Loot History'!$B:$B,0)),""))
D32: Tommypenn-Thunderstrike | E32: =IF(D32="","",COUNTIF('Loot History'!$A:$A,D32)) -> 8 | F32: =IF(D32="","",COUNTIFS('Loot History'!$A:$A,D32,'Loot History'!$G:$G,"BiS")) -> 4 | G32: =IF(D32="","",COUNTIFS('Loot History'!$A:$A,D32,'Loot History'!$G:$G,"2nd BiS")) -> 0 | H32: =IF(D32="","",COUNTIFS('Loot History'!$A:$A,D32,'Loot History'!$G:$G,"Upgrade")) -> 0 | I32: =IF(D32="","",COUNTIFS('Loot History'!$A:$A,D32,'Loot History'!$G:$G,"Offspecc")) -> 4 | J32: =IF(D32="","",COUNTIFS('Loot History'!$A:$A,D32,'Loot History'!$G:$G,"Passen")) -> 0 | K32: =IF(D32="","",IFERROR(E32-F32-G32-H32-I32-J32,0)) -> 0 | L32: =IF(D32="","",IFERROR(INDEX('Loot History'!$I:$I,MATCH(D32,'Loot History'!$A:$A,0)),"")) -> SHAMAN | AA32: =IF(Z32="","",COUNTIF('Loot History'!$B:$B,Z32)) | AB32: =IF(Z32="","",IFERROR(INDEX('Loot History'!$J:$J,MATCH(Z32,'Loot History'!$B:$B,0)),""))
D33: Tuarendrood-Thunderstrike | AA33: =IF(Z33="","",COUNTIF('Loot History'!$B:$B,Z33)) | AB33: =IF(Z33="","",IFERROR(INDEX('Loot History'!$J:$J,MATCH(Z33,'Loot History'!$B:$B,0)),""))
D34: Xænd-Thunderstrike | AA34: =IF(Z34="","",COUNTIF('Loot History'!$B:$B,Z34)) | AB34: =IF(Z34="","",IFERROR(INDEX('Loot History'!$J:$J,MATCH(Z34,'Loot History'!$B:$B,0)),""))
D35: Xaganat-Thunderstrike | AA35: =IF(Z35="","",COUNTIF('Loot History'!$B:$B,Z35)) | AB35: =IF(Z35="","",IFERROR(INDEX('Loot History'!$J:$J,MATCH(Z35,'Loot History'!$B:$B,0)),""))
D36: Zabipala-Thunderstrike | AA36: =IF(Z36="","",COUNTIF('Loot History'!$B:$B,Z36)) | AB36: =IF(Z36="","",IFERROR(INDEX('Loot History'!$J:$J,MATCH(Z36,'Loot History'!$B:$B,0)),""))
D37: Zerleger-Thunderstrike | AA37: =IF(Z37="","",COUNTIF('Loot History'!$B:$B,Z37)) | AB37: =IF(Z37="","",IFERROR(INDEX('Loot History'!$J:$J,MATCH(Z37,'Loot History'!$B:$B,0)),""))
D38: Zzou-Thunderstrike | AA38: =IF(Z38="","",COUNTIF('Loot History'!$B:$B,Z38)) | AB38: =IF(Z38="","",IFERROR(INDEX('Loot History'!$J:$J,MATCH(Z38,'Loot History'!$B:$B,0)),""))
AA39: =IF(Z39="","",COUNTIF('Loot History'!$B:$B,Z39)) | AB39: =IF(Z39="","",IFERROR(INDEX('Loot History'!$J:$J,MATCH(Z39,'Loot History'!$B:$B,0)),""))
AA40: =IF(Z40="","",COUNTIF('Loot History'!$B:$B,Z40)) | AB40: =IF(Z40="","",IFERROR(INDEX('Loot History'!$J:$J,MATCH(Z40,'Loot History'!$B:$B,0)),""))
...
